Workbook

Sheet Matriz 30 descriptores
A1: Descriptor | B1: Código | C1: Unidad de aprendizaje | D1: Aprendizaje(s) esperado(s) | E1: AMO | F1: Actividad mínima obligatoria / indicación | G1: Docente
A2: Gestión de la Producción Agrícola | B2: AGA552 | C2: 1. Manejos técnicos y estados fenológicos | D2: 1.1 Relaciona los procesos fisiológicos con los estados fenológicos de los cultivos, para fundamentar decisiones de manejo técnico orientadas a mejorar el rendimiento, considerando condiciones agroclimáticas específicas. | E2: Sí | F2: Visita a predio (6 h aprox.): análisis de estados vegetativos, manejos productivos, procesos fisiológicos, estados fenológicos y condiciones agroclimáticas; investigación previa con fuentes oficiales y apoyo guiado de IAGen. | G2: =LOOKUP(MatrizDescriptores[[#This Row],[Código]],Hoja2!$A$2:$C$52) -> Saravia Martinez Antonio Javier
A3: Gestión de la Producción Agrícola | B3: AGA552 | C3: 2. Producción de semillas y requerimientos agroindustriales | D3: 2.1 Integra tecnología productiva en función de los requerimientos específicos de los cultivos, para optimizar el rendimiento y cumplir con estándares de calidad, considerando las demandas de los mercados de semillas y la agroindustria. | E3: Sí | F3: Visita a industria de producción agrícola, semillero o unidad productiva (6 h aprox.): relacionar manejos técnicos con requisitos de calidad, procesamiento, normativa y destino productivo. | G3: =LOOKUP(MatrizDescriptores[[#This Row],[Código]],Hoja2!$A$2:$C$52) -> Saravia Martinez Antonio Javier
A4: Gestión de la Producción Agrícola | B4: AGA552 | C4: 3. Diversificación de cultivos y rotación productiva | D4: 3.1 Desarrolla planes de manejo de cultivos, para optimizar el rendimiento y la calidad de la producción, considerando la eficiencia productiva del predio, las condiciones edafoclimáticas, la demanda de mercado y el uso sustentable de los recursos. | E4: Sí | F4: Planificación predial (4 h aprox.): informe grupal con cultivos pertinentes al territorio, eficiencia productiva, rotación, conservación de suelo, demanda de mercado y proyección del plan. | G4: =LOOKUP(MatrizDescriptores[[#This Row],[Código]],Hoja2!$A$2:$C$52) -> Saravia Martinez Antonio Javier
A5: Agricultura Sustentable | B5: ASAS03 | C5: 1. Desarrollo sostenible y agricultura | D5: 1.1 Fundamenta las bases del desarrollo productivo de manera sustentable, a partir de enfoques y métodos creativos relacionados a las dimensiones que se vinculan a la mantención del equilibrio del medio. 1.2 Argumenta las razones del desarrollo de alternativas productivas agropecuarias sustentables, a partir del impacto ambiental que deriva de la agricultura tradicional. | E5: Sí | F5: Presentación grupal e informe sobre desarrollo sostenible y pilares de sustentabilidad; foro sobre agricultura tradicional versus sustentable; salida a terreno sobre agricultura sustentable en Chile. | G5: =LOOKUP(MatrizDescriptores[[#This Row],[Código]],Hoja2!$A$2:$C$52) -> Acevedo Aguayo Mario Eduardo
A6: Agricultura Sustentable | B6: ASAS03 | C6: 2. Agricultura sustentable | D6: 2.1 Evalúa las interacciones de los distintos componentes bióticos y abióticos que forman parte de la integración y sinergia de los agroecosistemas, utilizando enfoques y métodos creativos relativos a los principios agroecológicos. 2.2 Fundamenta los principios del manejo sustentable de recursos de agroecosistemas, conforme a las interacciones y características productivas de las explotaciones agropecuarias. | E6: Sí | F6: Demostración didáctica grupal sobre elementos del medio ambiente, conceptos agroecológicos, dinámica de comunidades y poblaciones e interacciones con el medio. | G6: =LOOKUP(MatrizDescriptores[[#This Row],[Código]],Hoja2!$A$2:$C$52) -> Acevedo Aguayo Mario Eduardo
A7: Agricultura Sustentable | B7: ASAS03 | C7: 3. Sustentabilidad en la empresa | D7: 3.1 Planifica la implementación de medidas y estrategias relacionadas a la gestión de cambio hacia un sistema productivo sustentable, utilizando enfoques y métodos creativos, relacionados con las características de la empresa y su entorno. 3.2 Fundamenta la relevancia de los marcos políticos e institucionales con los que deben contar las empresas, conforme a los beneficios que entregan al desarrollo de un sistema productivo sustentable. | E7: Sí | F7: Caso grupal para categorizar problemas ambientales y plantear una metodología de cambio hacia la sostenibilidad; análisis de un problema o suceso real en sustentabilidad. | G7: =LOOKUP(MatrizDescriptores[[#This Row],[Código]],Hoja2!$A$2:$C$52) -> Acevedo Aguayo Mario Eduardo
A8: Cultivos Intensivos y Sistemas Hidropónicos | B8: AGD404 | C8: 1. Sistemas hidropónicos | D8: 1.1 Implementa un sistema de cultivo hidropónico, para especies vegetales, de alta eficiencia de acuerdo con los requerimientos ambientales y nutricionales, considerando el trabajo colaborativo y comunicación. | E8: Sí | F8: Actividad 1 (6 h): identificación de componentes y funcionamiento, trasplante de almácigos y puesta en marcha del sistema. Actividad 2 (6 h): preparación y ajuste de solución nutritiva, evaluación del cultivo y parámetros del sistema. | G8: =LOOKUP(MatrizDescriptores[[#This Row],[Código]],Hoja2!$A$2:$C$52) -> Vallejos Catrilao Gonzalo Hernán
A9: Cultivos Intensivos y Sistemas Hidropónicos | B9: AGD404 | C9: 2. Producción de cultivos controlados | D9: 2.1 Aplica técnicas de control ambiental, para especies vegetales, de acuerdo con los requerimientos climáticos y fisiológicos de los cultivos, considerando resolución de problemas, innovación y emprendimiento. | E9: Sí | F9: Actividad 1 (3 h): identificación del control climático y montaje de ensayo comparativo entre ambiente controlado y aire libre. Actividad 2 (3 h): evaluación y cuantificación del crecimiento y comparación de resultados. | G9: =LOOKUP(MatrizDescriptores[[#This Row],[Código]],Hoja2!$A$2:$C$52) -> Vallejos Catrilao Gonzalo Hernán
A10: Desarrollo Mercado Exportador | B10: AGE504 | C10: 1. Evaluación de mercados potenciales exportables | D10: 1.1 Analiza el mercado exportador, para introducir un producto o servicio agrícola y/o agroindustrial utilizando enfoques creativos en el desarrollo de la profesión. | E10: Sí | F10: Investigación de mercados potenciales (3 h) y análisis de necesidades del mercado (3 h), ventajas competitivas y comparativas de productos chilenos. | G10: =LOOKUP(MatrizDescriptores[[#This Row],[Código]],Hoja2!$A$2:$C$52) -> Sandoval Zapata Lorena Beatriz
A11: Desarrollo Mercado Exportador | B11: AGE504 | C11: 2. Desarrollo de estrategias exportadora | D11: 2.1 Crea el flujo de producto por clientes, de origen agropecuario, para encontrar una estrategia básica viable, equilibrada económicamente, de acuerdo al modelo de libre mercado desde una perspectiva ética y ciudadana. | E11: Sí | F11: Determinación de mercado potencial y canales (3 h) y generación de estrategia de negocio (3 h), considerando costos, mercado meta y planes tácticos/operativos. | G11: =LOOKUP(MatrizDescriptores[[#This Row],[Código]],Hoja2!$A$2:$C$52) -> Sandoval Zapata Lorena Beatriz
A12: Desarrollo Mercado Exportador | B12: AGE504 | C12: 3. Implementación de plan estratégico | D12: 3.1 Recomienda los procesos de una exportación, mediante el uso de TIC para dar soluciones creativas y eficientes a los desafíos relacionados con el proceso exportador de productos de origen agropecuario. | E12: Sí | F12: Recolección y completación de documentos de exportación (3 h) y elaboración de flujograma del proceso exportador (3 h), identificando problemas y soluciones. | G12: =LOOKUP(MatrizDescriptores[[#This Row],[Código]],Hoja2!$A$2:$C$52) -> Sandoval Zapata Lorena Beatriz
A13: Diseño de Planes de Producción Agrícola | B13: AGD409 | C13: 1. Factores técnicos y ambientales en la producción agrícola | D13: 1.1 Analiza los principales factores ambientales y técnicos que influyen en la producción agrícola, para el desarrollo de un plan de producción agrícola, considerando criterios de sostenibilidad y normativas, desde la perspectiva de la ética y la ciudadanía. | E13: Sí | F13: Factores Ambientales (9 h aprox.): investigación bibliográfica grupal sobre factores ambientales sustentables y sostenibles de un sistema de producción agrícola. | G13: =LOOKUP(MatrizDescriptores[[#This Row],[Código]],Hoja2!$A$2:$C$52) -> Sandoval Zapata Lorena Beatriz
... A99: Uso de Agroquímicos y Aseguramiento de la Calidad | B99: AGA306 | C99: 4. Unidad integradora de la competencia de egreso | D99: 4.1 Planifica un programa fitosanitario de aplicación de agroquímicos para una especie hortícola, considerando los mercados de destino, el impacto medioambiental, y el aseguramiento de la calidad del producto. | E99: Definida por área | F99: Remítase al diseño instruccional diseñado por el área académica. | G99: =LOOKUP(MatrizDescriptores[[#This Row],[Código]],Hoja2!$A$2:$C$52) -> Acevedo Aguayo Mario Eduardo

Sheet Hoja3
A1: Id | B1: Asignatura | C1: Código | D1: Unidad de aprendizaje
A2: 1 | B2: Gestión de la Producción Agrícola | C2: AGA552 | D2: 1. Manejos técnicos y estados fenológicos
A3: AGA552 | C3: AGA552 | D3: 2. Producción de semillas y requerimientos agroindustriales
A4: AGA552 | C4: AGA552 | D4: 3. Diversificación de cultivos y rotación productiva
A5: 2 | B5: Agricultura Sustentable | C5: ASAS03 | D5: 1. Desarrollo sostenible y agricultura
A6: ASAS03 | C6: ASAS03 | D6: 2. Agricultura sustentable
A7: ASAS03 | C7: ASAS03 | D7: 3. Sustentabilidad en la empresa
A8: 3 | B8: Cultivos Intensivos y Sistemas Hidropónicos | C8: AGD404 | D8: 1. Sistemas hidropónicos
A9: AGD404 | C9: AGD404 | D9: 2. Producción de cultivos controlados
A10: 4 | B10: Desarrollo Mercado Exportador | C10: AGE504 | D10: 1. Evaluación de mercados potenciales exportables
A11: AGE504 | C11: AGE504 | D11: 2. Desarrollo de estrategias exportadora
A12: AGE504 | C12: AGE504 | D12: 3. Implementación de plan estratégico
A13: 5 | B13: Diseño de Planes de Producción Agrícola | C13: AGD409 | D13: 1. Factores técnicos y ambientales en la producción agrícola
A14: AGD409 | C14: AGD409 | D14: 2. Formulación de planes de producción en sistemas agrícolas
A15: AGD409 | C15: AGD409 | D15: 3. Diseño de un plan de producción agrícola
A16: 6 | B16: Formulación y Evaluación de Proyectos | C16: COFE04 | D16: 1. Descripción, proyección del mercado, tamaño y localización de un proyecto agropecuario
A17: COFE04 | C17: COFE04 | D17: 2. Formulación y preparación de proyectos agropecuarios
A18: COFE04 | C18: COFE04 | D18: 3. Evaluación de proyectos agropecuarios
A19: 7 | B19: Fruticultura | C19: AGO432 | D19: 1. Introducción a la Fruticultura
A20: AGO432 | C20: AGO432 | D20: 2. Propagación y establecimiento de un huerto frutal
A21: AGO432 | C21: AGO432 | D21: 3. Manejo del huerto frutal
A22: AGO432 | C22: AGO432 | D22: 4. Manejos específicos productivos en las principales especies frutales
A23: 8 | B23: Fruticultura Aplicada | C23: AGO551 | D23: 1. Introducción a las especies frutales en Chile y el mundo
A24: AGO551 | C24: AGO551 | D24: 2. Características y manejos técnicos de especies tradicionales, no tradicionales y frutales menores en Chile
A25: AGO551 | C25: AGO551 | D25: 3. Importancia estratégica de especies tradicionales, no tradicionales y frutales menores en Chile
A26: 9 | B26: Fundamentos de Plagas, Enfermedades y Malezas | C26: AGO312 | D26: 1. Plagas de importancia agrícola
A27: AGO312 | C27: AGO312 | D27: 2. Enfermedades de importancia agrícola
A28: AGO312 | C28: AGO312 | D28: 3. Malezas de importancia agrícola
A29: 10 | B29: Gestión de Calidad Agrícola | C29: AGE441 | D29: 1. Conceptos, procesos y marco normativo de la gestión de calidad
A30: AGE441 | C30: AGE441 | D30: 2. Sistemas, modelos de gestión de aseguramiento de calidad, certificación y normativa específica
A31: AGE441 | C31: AGE441 | D31: 3. Técnicas, instrumentos y herramientas de gestión en procesos de certificación
A32: 11 | B32: Prevención y Control de Plagas, Enfermedades y Malezas | C32: AGB121 | D32: 1. Manejo integrado de plagas, enfermedades y malezas
A33: AGB121 | C33: AGB121 | D33: 2. Manejo y uso de plaguicidas agrícolas
A34: AGB121 | C34: AGB121 | D34: 3. Buenas prácticas agrícolas en manejo de plagas, enfermedades y malezas
A35: 12 | B35: Gestión de Labores Agrícolas | C35: AGD331 | D35: 1. Organización de labores agrícolas
A36: AGD331 | C36: AGD331 | D36: 2. Coordinación de labores agrícolas
A37: AGD331 | C37: AGD331 | D37: 3. Control de labores agrícolas
A38: AGD331 | C38: AGD331 | D38: 4. Unidad integradora para evaluar la competencia
A39: 13 | B39: Gestión de Riesgos Climáticos | C39: AGE502 | D39: 1. Variables climáticas
A40: AGE502 | C40: AGE502 | D40: 2. Riesgos y oportunidades climáticas
...

Sheet Hoja1

Sheet Resumen
A1: Código | B1: Descriptor | C1: N° unidades | D1: Tipo de AMO | F1: Criterio utilizado
A2: AGA552 | B2: Gestión de la Producción Agrícola | C2: 3 | D2: Sí | F2: AMO = Actividad Mínima Obligatoria. “Sí”: el descriptor especifica una actividad concreta. “A definir por docente”: el descriptor deja la actividad a criterio del docente. “Definida por área”: el descriptor remite al diseño instruccional centralizado del área. Los aprendizajes esperados se mantuvieron con la redacción del descriptor; las actividades se sintetizaron para facilitar lectura.
A3: ASAS03 | B3: Agricultura Sustentable | C3: 3 | D3: Sí
A4: AGD404 | B4: Cultivos Intensivos y Sistemas Hidropónicos | C4: 2 | D4: Sí
A5: AGE504 | B5: Desarrollo Mercado Exportador | C5: 3 | D5: Sí
A6: AGD409 | B6: Diseño de Planes de Producción Agrícola | C6: 3 | D6: A definir por docente, Sí
A7: COFE04 | B7: Formulación y Evaluación de Proyectos | C7: 3 | D7: Sí
A8: AGO432 | B8: Fruticultura | C8: 4 | D8: Sí
A9: AGO551 | B9: Fruticultura Aplicada | C9: 3 | D9: Sí
A10: AGO312 | B10: Fundamentos de Plagas, Enfermedades y Malezas | C10: 3 | D10: Sí
A11: AGE441 | B11: Gestión de Calidad Agrícola | C11: 3 | D11: A definir por docente, Sí
A12: AGB121 | B12: Prevención y Control de Plagas, Enfermedades y Malezas | C12: 3 | D12: A definir por docente, Sí
A13: AGD331 | B13: Gestión de Labores Agrícolas | C13: 4 | D13: Definida por área
A14: AGE502 | B14: Gestión de Riesgos Climáticos | C14: 3 | D14: Sí
... A31: AGA306 | B31: Uso de Agroquímicos y Aseguramiento de la Calidad | C31: 4 | D31: Definida por área

Sheet Hoja2
A1: Codigo | B1: Asignatura | C1: Profesor | F1: Código
A2: AGA305 | B2: Tecnologías De Proceso Y Almacenamiento | C2: Sandoval Zapata Lorena Beatriz | F2: AGA305 | G2: =LOOKUP(F2,$A$2:$C$52) -> Sandoval Zapata Lorena Beatriz
A3: AGA306 | B3: Uso De Agroquímicos Y Aseguramiento De La Calidad | C3: Acevedo Aguayo Mario Eduardo | F3: AGA305 | G3: =LOOKUP(F3,$A$2:$C$52) -> Sandoval Zapata Lorena Beatriz
A4: AGA551 | B4: Tecnologías De Riego Y Gestión Del Agua | C4: Vallejos Catrilao Gonzalo Hernán | F4: AGA305 | G4: =LOOKUP(F4,$A$2:$C$52) -> Sandoval Zapata Lorena Beatriz
A5: AGA552 | B5: Gestión De La Producción Agrícola | C5: Saravia Martinez Antonio Javier | F5: AGA306 | G5: =LOOKUP(F5,$A$2:$C$52) -> Acevedo Aguayo Mario Eduardo
A6: AGB121 | B6: Prevención Y Control De Plagas, Enfermedades Y Malezas | C6: Saravia Martinez Antonio Javier | F6: AGA306 | G6: =LOOKUP(F6,$A$2:$C$52) -> Acevedo Aguayo Mario Eduardo
A7: AGB122 | B7: Taller De Prácticas Agrícolas Sostenibles | C7: Acevedo Aguayo Mario Eduardo | F7: AGA306 | G7: =LOOKUP(F7,$A$2:$C$52) -> Acevedo Aguayo Mario Eduardo
A8: AGC221 | B8: Sistemas De Riego | C8: Vallejos Catrilao Gonzalo Hernán | F8: AGA306 | G8: =LOOKUP(F8,$A$2:$C$52) -> Acevedo Aguayo Mario Eduardo
A9: AGC306 | B9: Negocios Agrícolas | C9: Gutiérrez Vásquez Luis Anibal | F9: AGA551 | G9: =LOOKUP(F9,$A$2:$C$52) -> Vallejos Catrilao Gonzalo Hernán
A10: AGD331 | B10: Gestión De Labores Agrícolas | C10: Saravia Martinez Antonio Javier | F10: AGA551 | G10: =LOOKUP(F10,$A$2:$C$52) -> Vallejos Catrilao Gonzalo Hernán
A11: AGD404 | B11: Cultivos Intensivos Y Sistemas Hidropónicos | C11: Vallejos Catrilao Gonzalo Hernán | F11: AGA551 | G11: =LOOKUP(F11,$A$2:$C$52) -> Vallejos Catrilao Gonzalo Hernán
A12: AGD405 | B12: Plan De Marketing De Productos Y Servicios | C12: García Moscoso Richard Fabian | F12: AGA552 | G12: =LOOKUP(F12,$A$2:$C$52) -> Saravia Martinez Antonio Javier
A13: AGD409 | B13: Diseño De Planes De Producción Agrícola | C13: Sandoval Zapata Lorena Beatriz | F13: AGA552 | G13: =LOOKUP(F13,$A$2:$C$52) -> Saravia Martinez Antonio Javier
... A52: PAGC24 | B52: Gestión Para La Certificación | C52: Sandoval Zapata Lorena Beatriz | F52: AGE506 | G52: =LOOKUP(F52,$A$2:$C$52) -> Vidal Carrasco Pilar Gabriela
F53: AGE506 | G53: =LOOKUP(F53,$A$2:$C$52) -> Vidal Carrasco Pilar Gabriela
F54: AGE506 | G54: =LOOKUP(F54,$A$2:$C$52) -> Vidal Carrasco Pilar Gabriela
F55: AGG403 | G55: =LOOKUP(F55,$A$2:$C$52) -> Cruces Soto Sonia Margoth
F56: AGG403 | G56: =LOOKUP(F56,$A$2:$C$52) -> Cruces Soto Sonia Margoth
F57: AGG403 | G57: =LOOKUP(F57,$A$2:$C$52) -> Cruces Soto Sonia Margoth
F58: AGI002 | G58: =LOOKUP(F58,$A$2:$C$52) -> Sandoval Zapata Lorena Beatriz
F59: AGI002 | G59: =LOOKUP(F59,$A$2:$C$52) -> Sandoval Zapata Lorena Beatriz
F60: AGI002 | G60: =LOOKUP(F60,$A$2:$C$52) -> Sandoval Zapata Lorena Beatriz
F61: AGI002 | G61: =LOOKUP(F61,$A$2:$C$52) -> Sandoval Zapata Lorena Beatriz
F62: AGO312 | G62: =LOOKUP(F62,$A$2:$C$52) -> Saravia Martinez Antonio Javier
F63: AGO312 | G63: =LOOKUP(F63,$A$2:$C$52) -> Saravia Martinez Antonio Javier
F64: AGO312 | G64: =LOOKUP(F64,$A$2:$C$52) -> Saravia Martinez Antonio Javier
... F99: PAGC24 | G99: =LOOKUP(F99,$A$2:$C$52) -> Sandoval Zapata Lorena Beatriz
